Workbook

Sheet 实验设置
A1: 平抛运动实验｜空中轨迹与光电门测速
A3: 同一批次固定物体、光电门位置、抛出点高度和相机设置；每个 Trial 记录光电门 block time，并自动计算瞬时速度。
A5: 填写项目 | B5: 填写值
A6: 手机型号 | B6: iPhone 12
A7: 录像模式 | B7: 1080p / 240 fps（慢动作）
A8: 物体种类 | B8: 大钢球
A9: 物体直径_mm | B9: 23.7
A10: 物体质量_g | B10: 4.16
A11: 物体体积_cm3 | B11: =IF(B9>0,PI()/6*(B9/10)^3,"") -> 6.9701747
A12: 物体密度_g_cm3 | B12: =IF(B11>0,B10/B11,"") -> 0.59682866
A13: 光电门型号或编号
A14: 光电门位置 | B14: 轨道出口前1.2cm
A15: 抛出点距地面高度_cm | B15: 77
A16: 整体备注
A19: 自动计算：球体体积 V = πd³/6；密度 ρ = m/V；瞬时速度 v = d/Δt。使用 mm 和 ms 时，d ÷ block time 的数值单位直接为 m/s。

Sheet Trial记录
A1: Trial 记录｜每段视频一行
A3: 人工填写视频文件名和光电门 block time；瞬时速度自动计算，空中轨迹后续从原始视频自动提取。
A5: Trial编号 | B5: 视频文件名 | C5: 光电门block_time_ms | D5: 瞬时速度_m_s | E5: 是否更换背景 | F5: 背景说明（可空） | G5: 备注（可空）
A6: T001 | B6: IMG_0625 | C6: 0.03389 | D6: =IF(C6>0,IF(实验设置!$B$9>0,实验设置!$B$9/C6,""),"") -> 699.32133 | G6: 10°42.5cm
A7: T002 | B7: IMG_0626 | C7: 0.03365 | D7: =IF(C7>0,IF(实验设置!$B$9>0,实验设置!$B$9/C7,""),"") -> 704.30906 | G7: 10°42.5cm
A8: T003 | B8: IMG_0627 | C8: 0.03328 | D8: =IF(C8>0,IF(实验设置!$B$9>0,实验设置!$B$9/C8,""),"") -> 712.13942 | G8: 10°42.5cm
A9: T004 | B9: IMG_0629 | C9: 0.03344 | D9: =IF(C9>0,IF(实验设置!$B$9>0,实验设置!$B$9/C9,""),"") -> 708.73206 | G9: 10°42.5cm
A10: T005 | B10: IMG_0630 | C10: 0.03384 | D10: =IF(C10>0,IF(实验设置!$B$9>0,实验设置!$B$9/C10,""),"") -> 700.35461 | G10: 10°42.5cm
A11: T006 | B11: IMG_0642 | C11: 0.03372 | E11: 是 | F11: 黑色 | G11: 10°42.5cm
A12: T007 | B12: IMG_0643 | C12: 0.034 | E12: 是 | F12: 黑色 | G12: 10°42.5cm
A13: T008 | B13: IMG_0644 | C13: 0.03391 | E13: 是 | F13: 黑色 | G13: 10°42.5cm
A14: T009 | B14: IMG_0645 | C14: 0.03445 | E14: 是 | F14: 黑色 | G14: 10°42.5cm
A15: T010 | B15: IMG_0646 | C15: 0.03377 | E15: 是 | F15: 黑色 | G15: 10°42.5cm
A16: T011 | B16: IMG_0631 | C16: 0.02522 | G16: 10°72.5cm
A17: T012 | B17: IMG_0632 | C17: 0.02537 | G17: 10°72.5cm
A18: T013 | B18: IMG_0633 | C18: 0.0255 | G18: 10°72.5cm
A19: T014 | B19: IMG_0634 | C19: 0.0254 | G19: 10°72.5cm
A20: T015 | B20: IMG_0635 | C20: 0.02544 | G20: 10°72.5cm
A21: T016 | B21: IMG_0647 | C21: 0.02537 | E21: 是 | F21: 黑色 | G21: 10°72.5cm
A22: T017 | B22: IMG_0649 | C22: 0.02533 | E22: 是 | F22: 黑色 | G22: 10°72.5cm
A23: T018 | B23: IMG_0651 | C23: 0.02537 | E23: 是 | F23: 黑色 | G23: 10°72.5cm
A24: T019 | B24: IMG_0652 | C24: 0.0254 | E24: 是 | F24: 黑色 | G24: 10°72.5cm
A25: T020 | B25: IMG_0653 | C25: 0.02533 | E25: 是 | F25: 黑色 | G25: 10°72.5cm
A26: T021 | B26: IMG_0637 | C26: 0.02139 | D26: =IF(C26>0,IF(实验设置!$B$9>0,实验设置!$B$9/C26,""),"") -> 1107.9944 | G26: 10°80.5cm
A27: T022 | B27: IMG_0638 | C27: 0.02138 | D27: =IF(C27>0,IF(实验设置!$B$9>0,实验设置!$B$9/C27,""),"") -> 1108.5126 | G27: 10°80.5cm
A28: T023 | B28: IMG_0639 | C28: 0.02145 | D28: =IF(C28>0,IF(实验设置!$B$9>0,实验设置!$B$9/C28,""),"") -> 1104.8951 | G28: 10°80.5cm
A29: T024 | B29: IMG_0640 | C29: 0.02153 | D29: =IF(C29>0,IF(实验设置!$B$9>0,实验设置!$B$9/C29,""),"") -> 1100.7896 | G29: 10°80.5cm
A30: T025 | B30: IMG_0641 | C30: 0.02146 | D30: =IF(C30>0,IF(实验设置!$B$9>0,实验设置!$B$9/C30,""),"") -> 1104.3802 | G30: 10°80.5cm
A31: T026 | B31: IMG_0654 | C31: 0.02152 | E31: 是 | F31: 黑色 | G31: 10°80.5cm
A32: T027 | B32: IMG_0655 | C32: 0.0215 | E32: 是 | F32: 黑色 | G32: 10°80.5cm
A33: T028 | B33: IMG_0656 | C33: 0.02148 | E33: 是 | F33: 黑色 | G33: 10°80.5cm
A34: T029 | B34: IMG_0657 | C34: 0.02149 | E34: 是 | F34: 黑色 | G34: 10°80.5cm
A35: T030 | B35: IMG_0658 | C35: 0.02147 | E35: 是 | F35: 黑色 | G35: 10°80.5cm
A36: T031 | D36: =IF(C36>0,IF(实验设置!$B$9>0,实验设置!$B$9/C36,""),"")
A37: T032 | D37: =IF(C37>0,IF(实验设置!$B$9>0,实验设置!$B$9/C37,""),"")
A38: T033 | D38: =IF(C38>0,IF(实验设置!$B$9>0,实验设置!$B$9/C38,""),"")
A39: T034 | D39: =IF(C39>0,IF(实验设置!$B$9>0,实验设置!$B$9/C39,""),"")
A40: T035 | D40: =IF(C40>0,IF(实验设置!$B$9>0,实验设置!$B$9/C40,""),"")
A41: T036
A42: T037
...
