Workbook

Sheet 实验设置
A1: 斜面滑动实验｜最小计算记录表
A3: 同一批次固定物体、质量、轨道材质、动摩擦系数、相机位置和释放点；Trial中只改变角度或背景。
A5: 填写项目 | B5: 填写值 | C5: 简单示例 | D5: 为什么保留
A6: 实验批次名称 | B6: 20260723_incline_01 | C6: 例：20260723_incline_01 | D6: 用于文件夹和 metadata 命名
A7: 采集日期 | B7: 2026.07.23 | C7: 填写当天日期 | D7: 不用填写具体时间
A8: 手机型号 | B8: iPhone 12 | C8: 已预填 | D8: 设备不变时无需修改
A9: 录像模式 | B9: 高清/240fps（慢动作） | C9: 例：高清 / 240 fps | D9: 分辨率和帧率写在一起即可
A10: 物体说明 | B10: 黑底圆孔滑块 | C10: 例：木块A | D10: 本批次只使用一个物体
A11: 物体质量_kg | B11: 0.08768 | C11: 例：0.200 | D11: 同一批次固定
A12: 轨道材质 | B12: 木板原表面 | C12: 例：木板原表面 | D12: 更换材质时建立新批次
A13: 动摩擦系数_mu_k | B13: 0.463 | C13: 例：0.250 | D13: 同一批次固定
A14: 标定参照长度_cm | B14: 49 | C14: 画面中标尺已知长度 | D14: 用于像素换算实际距离
A15: 固定释放点 | B15: 顶端 | C15: 例：顶端红色胶带线 | D15: 不要求精确测量距离
A16: 重力加速度_m_s2 | B16: 9.80665 | C16: 已预填标准重力 | D16: 一般无需修改
A17: 整体备注 | B17: 滑块长11cm | C17: 没有异常可留空 | D17: 记录影响整批实验的情况
A20: 自动计算：每个 Trial 的摩擦力 F_f = μ_k·m·g·cos(θ)；理论加速度 a = g·[sin(θ) − μ_k·cos(θ)]。
A21: 背景变化不影响批次物理参数；在 Trial 记录中标记“是否更换背景”，用于 Appearance OOD 划分。

Sheet Trial记录
A1: Trial 记录｜每段视频一行
A3: 人工填写视频文件名、斜面角度和背景变化；摩擦力与理论加速度由批次固定参数自动计算。
A5: Trial编号 | B5: 视频文件名 | C5: 斜面角度_deg | D5: 摩擦力_N | E5: 理论加速度_m_s2 | F5: 是否更换背景 | G5: 背景说明（可空）
A6: T001 | B6: IMG_0271 | C6: 32 | D6: =IF(OR(B6="",C6="",实验设置!$B$11="",实验设置!$B$13=""),"",实验设置!$B$13*实验设置!$B$11*实验设置!$B$16*COS(RADIANS(C6))) -> 0.33761574 | E6: =IF(OR(B6="",C6="",实验设置!$B$13=""),"",实验设置!$B$16*(SIN(RADIANS(C6))-实验设置!$B$13*COS(RADIANS(C6)))) -> 1.3461882
A7: T002 | B7: IMG_0273 | C7: 32 | D7: =IF(OR(B7="",C7="",实验设置!$B$11="",实验设置!$B$13=""),"",实验设置!$B$13*实验设置!$B$11*实验设置!$B$16*COS(RADIANS(C7))) -> 0.33761574 | E7: =IF(OR(B7="",C7="",实验设置!$B$13=""),"",实验设置!$B$16*(SIN(RADIANS(C7))-实验设置!$B$13*COS(RADIANS(C7)))) -> 1.3461882
A8: T003 | B8: IMG_0274 | C8: 32 | D8: =IF(OR(B8="",C8="",实验设置!$B$11="",实验设置!$B$13=""),"",实验设置!$B$13*实验设置!$B$11*实验设置!$B$16*COS(RADIANS(C8))) -> 0.33761574 | E8: =IF(OR(B8="",C8="",实验设置!$B$13=""),"",实验设置!$B$16*(SIN(RADIANS(C8))-实验设置!$B$13*COS(RADIANS(C8)))) -> 1.3461882
A9: T004 | B9: IMG_0275 | C9: 32 | D9: =IF(OR(B9="",C9="",实验设置!$B$11="",实验设置!$B$13=""),"",实验设置!$B$13*实验设置!$B$11*实验设置!$B$16*COS(RADIANS(C9))) -> 0.33761574 | E9: =IF(OR(B9="",C9="",实验设置!$B$13=""),"",实验设置!$B$16*(SIN(RADIANS(C9))-实验设置!$B$13*COS(RADIANS(C9)))) -> 1.3461882
A10: T005 | B10: IMG_0276 | C10: 32 | D10: =IF(OR(B10="",C10="",实验设置!$B$11="",实验设置!$B$13=""),"",实验设置!$B$13*实验设置!$B$11*实验设置!$B$16*COS(RADIANS(C10))) -> 0.33761574 | E10: =IF(OR(B10="",C10="",实验设置!$B$13=""),"",实验设置!$B$16*(SIN(RADIANS(C10))-实验设置!$B$13*COS(RADIANS(C10)))) -> 1.3461882
A11: T006 | B11: IMG_0313 | C11: 32 | D11: =IF(OR(B11="",C11="",实验设置!$B$11="",实验设置!$B$13=""),"",实验设置!$B$13*实验设置!$B$11*实验设置!$B$16*COS(RADIANS(C11))) -> 0.33761574 | E11: =IF(OR(B11="",C11="",实验设置!$B$13=""),"",实验设置!$B$16*(SIN(RADIANS(C11))-实验设置!$B$13*COS(RADIANS(C11)))) -> 1.3461882 | F11: 是 | G11: 油画
A12: T007 | B12: IMG_0314 | C12: 32 | D12: =IF(OR(B12="",C12="",实验设置!$B$11="",实验设置!$B$13=""),"",实验设置!$B$13*实验设置!$B$11*实验设置!$B$16*COS(RADIANS(C12))) -> 0.33761574 | E12: =IF(OR(B12="",C12="",实验设置!$B$13=""),"",实验设置!$B$16*(SIN(RADIANS(C12))-实验设置!$B$13*COS(RADIANS(C12)))) -> 1.3461882 | F12: 是 | G12: 油画
A13: T008 | B13: IMG_0317 | C13: 32 | D13: =IF(OR(B13="",C13="",实验设置!$B$11="",实验设置!$B$13=""),"",实验设置!$B$13*实验设置!$B$11*实验设置!$B$16*COS(RADIANS(C13))) -> 0.33761574 | E13: =IF(OR(B13="",C13="",实验设置!$B$13=""),"",实验设置!$B$16*(SIN(RADIANS(C13))-实验设置!$B$13*COS(RADIANS(C13)))) -> 1.3461882 | F13: 是 | G13: 油画
A14: T009 | B14: IMG_0318 | C14: 32 | D14: =IF(OR(B14="",C14="",实验设置!$B$11="",实验设置!$B$13=""),"",实验设置!$B$13*实验设置!$B$11*实验设置!$B$16*COS(RADIANS(C14))) -> 0.33761574 | E14: =IF(OR(B14="",C14="",实验设置!$B$13=""),"",实验设置!$B$16*(SIN(RADIANS(C14))-实验设置!$B$13*COS(RADIANS(C14)))) -> 1.3461882 | F14: 是 | G14: 油画
A15: T010 | B15: IMG_0319 | C15: 32 | D15: =IF(OR(B15="",C15="",实验设置!$B$11="",实验设置!$B$13=""),"",实验设置!$B$13*实验设置!$B$11*实验设置!$B$16*COS(RADIANS(C15))) -> 0.33761574 | E15: =IF(OR(B15="",C15="",实验设置!$B$13=""),"",实验设置!$B$16*(SIN(RADIANS(C15))-实验设置!$B$13*COS(RADIANS(C15)))) -> 1.3461882 | F15: 是 | G15: 油画
A16: T011 | B16: IMG_0341 | C16: 32 | D16: =IF(OR(B16="",C16="",实验设置!$B$11="",实验设置!$B$13=""),"",实验设置!$B$13*实验设置!$B$11*实验设置!$B$16*COS(RADIANS(C16))) -> 0.33761574 | E16: =IF(OR(B16="",C16="",实验设置!$B$13=""),"",实验设置!$B$16*(SIN(RADIANS(C16))-实验设置!$B$13*COS(RADIANS(C16)))) -> 1.3461882 | F16: 是 | G16: 黑色泡沫板
A17: T012 | B17: IMG_0342 | C17: 32 | D17: =IF(OR(B17="",C17="",实验设置!$B$11="",实验设置!$B$13=""),"",实验设置!$B$13*实验设置!$B$11*实验设置!$B$16*COS(RADIANS(C17))) -> 0.33761574 | E17: =IF(OR(B17="",C17="",实验设置!$B$13=""),"",实验设置!$B$16*(SIN(RADIANS(C17))-实验设置!$B$13*COS(RADIANS(C17)))) -> 1.3461882 | F17: 是 | G17: 黑色泡沫板
A18: T013 | B18: IMG_0343 | C18: 32 | D18: =IF(OR(B18="",C18="",实验设置!$B$11="",实验设置!$B$13=""),"",实验设置!$B$13*实验设置!$B$11*实验设置!$B$16*COS(RADIANS(C18))) -> 0.33761574 | E18: =IF(OR(B18="",C18="",实验设置!$B$13=""),"",实验设置!$B$16*(SIN(RADIANS(C18))-实验设置!$B$13*COS(RADIANS(C18)))) -> 1.3461882 | F18: 是 | G18: 黑色泡沫板
A19: T014 | B19: IMG_0344 | C19: 32 | D19: =IF(OR(B19="",C19="",实验设置!$B$11="",实验设置!$B$13=""),"",实验设置!$B$13*实验设置!$B$11*实验设置!$B$16*COS(RADIANS(C19))) -> 0.33761574 | E19: =IF(OR(B19="",C19="",实验设置!$B$13=""),"",实验设置!$B$16*(SIN(RADIANS(C19))-实验设置!$B$13*COS(RADIANS(C19)))) -> 1.3461882 | F19: 是 | G19: 黑色泡沫板
A20: T015 | B20: IMG_0345 | C20: 32 | D20: =IF(OR(B20="",C20="",实验设置!$B$11="",实验设置!$B$13=""),"",实验设置!$B$13*实验设置!$B$11*实验设置!$B$16*COS(RADIANS(C20))) -> 0.33761574 | E20: =IF(OR(B20="",C20="",实验设置!$B$13=""),"",实验设置!$B$16*(SIN(RADIANS(C20))-实验设置!$B$13*COS(RADIANS(C20)))) -> 1.3461882 | F20: 是 | G20: 黑色泡沫板
A21: T016 | B21: IMG_0346 | C21: 32 | D21: =IF(OR(B21="",C21="",实验设置!$B$11="",实验设置!$B$13=""),"",实验设置!$B$13*实验设置!$B$11*实验设置!$B$16*COS(RADIANS(C21))) -> 0.33761574 | E21: =IF(OR(B21="",C21="",实验设置!$B$13=""),"",实验设置!$B$16*(SIN(RADIANS(C21))-实验设置!$B$13*COS(RADIANS(C21)))) -> 1.3461882 | F21: 是 | G21: 绿色卡纸
A22: T017 | B22: IMG_0348 | C22: 32 | D22: =IF(OR(B22="",C22="",实验设置!$B$11="",实验设置!$B$13=""),"",实验设置!$B$13*实验设置!$B$11*实验设置!$B$16*COS(RADIANS(C22))) -> 0.33761574 | E22: =IF(OR(B22="",C22="",实验设置!$B$13=""),"",实验设置!$B$16*(SIN(RADIANS(C22))-实验设置!$B$13*COS(RADIANS(C22)))) -> 1.3461882 | F22: 是 | G22: 绿色卡纸
... A25: T020 | B25: IMG_0351 | C25: 32 | D25: =IF(OR(B25="",C25="",实验设置!$B$11="",实验设置!$B$13=""),"",实验设置!$B$13*实验设置!$B$11*实验设置!$B$16*COS(RADIANS(C25))) -> 0.33761574 | E25: =IF(OR(B25="",C25="",实验设置!$B$13=""),"",实验设置!$B$16*(SIN(RADIANS(C25))-实验设置!$B$13*COS(RADIANS(C25)))) -> 1.3461882 | F25: 是 | G25: 绿色卡纸
A26: T021 | B26: IMG_0281 | C26: 35 | D26: =IF(OR(B26="",C26="",实验设置!$B$11="",实验设置!$B$13=""),"",实验设置!$B$13*实验设置!$B$11*实验设置!$B$16*COS(RADIANS(C26))) -> 0.32611196 | E26: =IF(OR(B26="",C26="",实验设置!$B$13=""),"",实验设置!$B$16*(SIN(RADIANS(C26))-实验设置!$B$13*COS(RADIANS(C26)))) -> 1.9055207
A27: T022 | B27: IMG_0283 | C27: 35 | D27: =IF(OR(B27="",C27="",实验设置!$B$11="",实验设置!$B$13=""),"",实验设置!$B$13*实验设置!$B$11*实验设置!$B$16*COS(RADIANS(C27))) -> 0.32611196 | E27: =IF(OR(B27="",C27="",实验设置!$B$13=""),"",实验设置!$B$16*(SIN(RADIANS(C27))-实验设置!$B$13*COS(RADIANS(C27)))) -> 1.9055207
A28: T023 | B28: IMG_0284 | C28: 35 | D28: =IF(OR(B28="",C28="",实验设置!$B$11="",实验设置!$B$13=""),"",实验设置!$B$13*实验设置!$B$11*实验设置!$B$16*COS(RADIANS(C28))) -> 0.32611196 | E28: =IF(OR(B28="",C28="",实验设置!$B$13=""),"",实验设置!$B$16*(SIN(RADIANS(C28))-实验设置!$B$13*COS(RADIANS(C28)))) -> 1.9055207
A29: T024 | B29: IMG_0285 | C29: 35 | D29: =IF(OR(B29="",C29="",实验设置!$B$11="",实验设置!$B$13=""),"",实验设置!$B$13*实验设置!$B$11*实验设置!$B$16*COS(RADIANS(C29))) -> 0.32611196 | E29: =IF(OR(B29="",C29="",实验设置!$B$13=""),"",实验设置!$B$16*(SIN(RADIANS(C29))-实验设置!$B$13*COS(RADIANS(C29)))) -> 1.9055207
A30: T025 | B30: IMG_0286 | C30: 35 | D30: =IF(OR(B30="",C30="",实验设置!$B$11="",实验设置!$B$13=""),"",实验设置!$B$13*实验设置!$B$11*实验设置!$B$16*COS(RADIANS(C30))) -> 0.32611196 | E30: =IF(OR(B30="",C30="",实验设置!$B$13=""),"",实验设置!$B$16*(SIN(RADIANS(C30))-实验设置!$B$13*COS(RADIANS(C30)))) -> 1.9055207
A31: T026 | B31: IMG_0320 | C31: 35 | D31: =IF(OR(B31="",C31="",实验设置!$B$11="",实验设置!$B$13=""),"",实验设置!$B$13*实验设置!$B$11*实验设置!$B$16*COS(RADIANS(C31))) -> 0.32611196 | E31: =IF(OR(B31="",C31="",实验设置!$B$13=""),"",实验设置!$B$16*(SIN(RADIANS(C31))-实验设置!$B$13*COS(RADIANS(C31)))) -> 1.9055207 | F31: 是 | G31: 油画
A32: T027 | B32: IMG_0321 | C32: 35 | D32: =IF(OR(B32="",C32="",实验设置!$B$11="",实验设置!$B$13=""),"",实验设置!$B$13*实验设置!$B$11*实验设置!$B$16*COS(RADIANS(C32))) -> 0.32611196 | E32: =IF(OR(B32="",C32="",实验设置!$B$13=""),"",实验设置!$B$16*(SIN(RADIANS(C32))-实验设置!$B$13*COS(RADIANS(C32)))) -> 1.9055207 | F32: 是 | G32: 油画
A33: T028 | B33: IMG_0323 | C33: 35 | D33: =IF(OR(B33="",C33="",实验设置!$B$11="",实验设置!$B$13=""),"",实验设置!$B$13*实验设置!$B$11*实验设置!$B$16*COS(RADIANS(C33))) -> 0.32611196 | E33: =IF(OR(B33="",C33="",实验设置!$B$13=""),"",实验设置!$B$16*(SIN(RADIANS(C33))-实验设置!$B$13*COS(RADIANS(C33)))) -> 1.9055207 | F33: 是 | G33: 油画
A34: T029 | B34: IMG_0324 | C34: 35 | D34: =IF(OR(B34="",C34="",实验设置!$B$11="",实验设置!$B$13=""),"",实验设置!$B$13*实验设置!$B$11*实验设置!$B$16*COS(RADIANS(C34))) -> 0.32611196 | E34: =IF(OR(B34="",C34="",实验设置!$B$13=""),"",实验设置!$B$16*(SIN(RADIANS(C34))-实验设置!$B$13*COS(RADIANS(C34)))) -> 1.9055207 | F34: 是 | G34: 油画
A35: T030 | B35: IMG_0325 | C35: 35 | D35: =IF(OR(B35="",C35="",实验设置!$B$11="",实验设置!$B$13=""),"",实验设置!$B$13*实验设置!$B$11*实验设置!$B$16*COS(RADIANS(C35))) -> 0.32611196 | E35: =IF(OR(B35="",C35="",实验设置!$B$13=""),"",实验设置!$B$16*(SIN(RADIANS(C35))-实验设置!$B$13*COS(RADIANS(C35)))) -> 1.9055207 | F35: 是 | G35: 油画
A36: T031 | B36: IMG_0375 | C36: 35 | D36: =IF(OR(B36="",C36="",实验设置!$B$11="",实验设置!$B$13=""),"",实验设置!$B$13*实验设置!$B$11*实验设置!$B$16*COS(RADIANS(C36))) -> 0.32611196 | E36: =IF(OR(B36="",C36="",实验设置!$B$13=""),"",实验设置!$B$16*(SIN(RADIANS(C36))-实验设置!$B$13*COS(RADIANS(C36)))) -> 1.9055207 | F36: 是 | G36: 黑色泡沫板
A37: T032 | B37: IMG_0376 | C37: 35 | D37: =IF(OR(B37="",C37="",实验设置!$B$11="",实验设置!$B$13=""),"",实验设置!$B$13*实验设置!$B$11*实验设置!$B$16*COS(RADIANS(C37))) -> 0.32611196 | E37: =IF(OR(B37="",C37="",实验设置!$B$13=""),"",实验设置!$B$16*(SIN(RADIANS(C37))-实验设置!$B$13*COS(RADIANS(C37)))) -> 1.9055207 | F37: 是 | G37: 黑色泡沫板
A38: T033 | B38: IMG_0377 | C38: 35 | D38: =IF(OR(B38="",C38="",实验设置!$B$11="",实验设置!$B$13=""),"",实验设置!$B$13*实验设置!$B$11*实验设置!$B$16*COS(RADIANS(C38))) -> 0.32611196 | E38: =IF(OR(B38="",C38="",实验设置!$B$13=""),"",实验设置!$B$16*(SIN(RADIANS(C38))-实验设置!$B$13*COS(RADIANS(C38)))) -> 1.9055207 | F38: 是 | G38: 黑色泡沫板
A39: T034 | B39: IMG_0378 | C39: 35 | D39: =IF(OR(B39="",C39="",实验设置!$B$11="",实验设置!$B$13=""),"",实验设置!$B$13*实验设置!$B$11*实验设置!$B$16*COS(RADIANS(C39))) -> 0.32611196 | E39: =IF(OR(B39="",C39="",实验设置!$B$13=""),"",实验设置!$B$16*(SIN(RADIANS(C39))-实验设置!$B$13*COS(RADIANS(C39)))) -> 1.9055207 | F39: 是 | G39: 黑色泡沫板
A40: T035 | B40: IMG_0379 | C40: 35 | D40: =IF(OR(B40="",C40="",实验设置!$B$11="",实验设置!$B$13=""),"",实验设置!$B$13*实验设置!$B$11*实验设置!$B$16*COS(RADIANS(C40))) -> 0.32611196 | E40: =IF(OR(B40="",C40="",实验设置!$B$13=""),"",实验设置!$B$16*(SIN(RADIANS(C40))-实验设置!$B$13*COS(RADIANS(C40)))) -> 1.9055207 | F40: 是 | G40: 黑色泡沫板
A41: T036 | B41: IMG_0352 | C41: 35 | D41: =IF(OR(B41="",C41="",实验设置!$B$11="",实验设置!$B$13=""),"",实验设置!$B$13*实验设置!$B$11*实验设置!$B$16*COS(RADIANS(C41))) -> 0.32611196 | E41: =IF(OR(B41="",C41="",实验设置!$B$13=""),"",实验设置!$B$16*(SIN(RADIANS(C41))-实验设置!$B$13*COS(RADIANS(C41)))) -> 1.9055207 | F41: 是 | G41: 绿色卡纸
A42: T037 | B42: IMG_0353 | C42: 35 | D42: =IF(OR(B42="",C42="",实验设置!$B$11="",实验设置!$B$13=""),"",实验设置!$B$13*实验设置!$B$11*实验设置!$B$16*COS(RADIANS(C42))) -> 0.32611196 | E42: =IF(OR(B42="",C42="",实验设置!$B$13=""),"",实验设置!$B$16*(SIN(RADIANS(C42))-实验设置!$B$13*COS(RADIANS(C42)))) -> 1.9055207 | F42: 是 | G42: 绿色卡纸
... A45: T040 | B45: IMG_0357 | C45: 35 | D45: =IF(OR(B45="",C45="",实验设置!$B$11="",实验设置!$B$13=""),"",实验设置!$B$13*实验设置!$B$11*实验设置!$B$16*COS(RADIANS(C45))) -> 0.32611196 | E45: =IF(OR(B45="",C45="",实验设置!$B$13=""),"",实验设置!$B$16*(SIN(RADIANS(C45))-实验设置!$B$13*COS(RADIANS(C45)))) -> 1.9055207 | F45: 是 | G45: 绿色卡纸
A46: T041 | B46: IMG_0287 | C46: 38 | D46: =IF(OR(B46="",C46="",实验设置!$B$11="",实验设置!$B$13=""),"",实验设置!$B$13*实验设置!$B$11*实验设置!$B$16*COS(RADIANS(C46))) -> 0.31371433 | E46: =IF(OR(B46="",C46="",实验设置!$B$13=""),"",实验设置!$B$16*(SIN(RADIANS(C46))-实验设置!$B$13*COS(RADIANS(C46)))) -> 2.4596304
...
