Workbook

Sheet 实验设置
A1: 竖直弹簧振子实验｜静止释放
A3: 装置为竖直悬挂式；整批实验统一从静止状态释放（初速度约为 0），固定小球和连接件，只更换弹簧、释放位移或背景。
A5: 填写项目 | B5: 填写值 | C5: 简单示例 | D5: 为什么保留
A6: 实验批次名称 | B6: 批次1 | C6: 例：20260729_spring_01 | D6: 用于文件夹和 metadata 命名
A7: 采集日期 | C7: 填写当天日期 | D7: 不用填写具体时间
A8: 手机型号 | B8: iPhone 12 | C8: 已预填 | D8: 设备不变时无需修改
A9: 录像模式 | B9: 1080p/240fps | C9: 例：4K / 60 fps 或 1080p / 120 fps | D9: 按实际录像设置填写
A10: 装置形式 | B10: 竖直悬挂式 | C10: 已预填 | D10: 明确重力方向与振动方向
A11: 小球编号 | B11: BALL-001 | C11: 例：BALL-001 | D11: 固定小球的唯一编号
A12: 小球种类 | B12: 钢球 | C12: 例：钢球 | D12: 同一批次不可更换
A13: 小球直径_mm | B13: 50 | C13: 例：30.00 | D13: 记录固定小球的外形尺寸
A14: 振动总质量_g | B14: 515.6 | C14: 例：100.00 | D14: 小球与所有随动连接件整体称量
A15: 重力加速度_m_s2 | B15: 9.80665 | C15: 已预填标准重力 | D15: 用于计算弹簧劲度系数
A16: 平衡位置标记方式 | C16: 例：装置旁标尺零点 | D16: 释放位移均相对平衡位置测量
A17: 释放方式 | B17: 静止释放 | C17: 整批固定 | D17: 释放前物体保持静止，初速度约为 0
A18: 整体备注 | C18: 没有异常可留空 | D18: 记录影响整批实验的情况
A21: 批次约束：小球及连接件保持不变；若更换小球、挂钩或随动配重，应新建实验批次。
A22: 位移约定：x₀ = 释放长度 − 平衡长度；两种长度必须从同一固定点量到同一物体参考点。向下为正，向上为负。

Sheet 弹簧设置
A1: 弹簧设置｜静态标定
A3: 黄色区域人工测量；浅蓝区域自动计算。每根弹簧挂上同一个振子后测量平衡长度，用静态伸长计算劲度系数和理论周期。
A5: 弹簧编号 | B5: 弹簧描述 | C5: 自然长度_mm | D5: 平衡长度_mm | E5: 静态伸长量_mm | F5: 劲度系数_N_m | G5: 理论周期_s | H5: 备注（可空）
A6: S01 | B6: 原装 | C6: 68 | D6: 223 | E6: =IF(AND(C6>0,D6>C6),D6-C6,"") -> 155 | F6: =IF(E6>0,实验设置!$B$14*实验设置!$B$15/E6,"") -> 32.621347 | G6: =IF(F6>0,2*PI()*SQRT((实验设置!$B$14/1000)/F6),"") -> 0.78992413 | H6: 42.55
A7: S02 | E7: =IF(AND(C7>0,D7>C7),D7-C7,"") | F7: =IF(E7>0,实验设置!$B$14*实验设置!$B$15/E7,"") -> #VALUE! | G7: =IF(F7>0,2*PI()*SQRT((实验设置!$B$14/1000)/F7),"") -> #VALUE!
A8: S03 | E8: =IF(AND(C8>0,D8>C8),D8-C8,"") | F8: =IF(E8>0,实验设置!$B$14*实验设置!$B$15/E8,"") -> #VALUE! | G8: =IF(F8>0,2*PI()*SQRT((实验设置!$B$14/1000)/F8),"") -> #VALUE!
A9: S04 | E9: =IF(AND(C9>0,D9>C9),D9-C9,"") | F9: =IF(E9>0,实验设置!$B$14*实验设置!$B$15/E9,"") -> #VALUE! | G9: =IF(F9>0,2*PI()*SQRT((实验设置!$B$14/1000)/F9),"") -> #VALUE!
A10: S05 | E10: =IF(AND(C10>0,D10>C10),D10-C10,"") | F10: =IF(E10>0,实验设置!$B$14*实验设置!$B$15/E10,"") -> #VALUE! | G10: =IF(F10>0,2*PI()*SQRT((实验设置!$B$14/1000)/F10),"") -> #VALUE!
A11: S06 | E11: =IF(AND(C11>0,D11>C11),D11-C11,"") | F11: =IF(E11>0,实验设置!$B$14*实验设置!$B$15/E11,"") -> #VALUE! | G11: =IF(F11>0,2*PI()*SQRT((实验设置!$B$14/1000)/F11),"") -> #VALUE!
A12: S07 | E12: =IF(AND(C12>0,D12>C12),D12-C12,"") | F12: =IF(E12>0,实验设置!$B$14*实验设置!$B$15/E12,"") -> #VALUE! | G12: =IF(F12>0,2*PI()*SQRT((实验设置!$B$14/1000)/F12),"") -> #VALUE!
A13: S08 | E13: =IF(AND(C13>0,D13>C13),D13-C13,"") | F13: =IF(E13>0,实验设置!$B$14*实验设置!$B$15/E13,"") -> #VALUE! | G13: =IF(F13>0,2*PI()*SQRT((实验设置!$B$14/1000)/F13),"") -> #VALUE!
A14: S09 | E14: =IF(AND(C14>0,D14>C14),D14-C14,"") | F14: =IF(E14>0,实验设置!$B$14*实验设置!$B$15/E14,"") -> #VALUE! | G14: =IF(F14>0,2*PI()*SQRT((实验设置!$B$14/1000)/F14),"") -> #VALUE!
A15: S10 | E15: =IF(AND(C15>0,D15>C15),D15-C15,"") | F15: =IF(E15>0,实验设置!$B$14*实验设置!$B$15/E15,"") -> #VALUE! | G15: =IF(F15>0,2*PI()*SQRT((实验设置!$B$14/1000)/F15),"") -> #VALUE!
A18: 自动计算：静态伸长量 ΔL = 平衡长度 − 自然长度；劲度系数 k = mg/ΔL；理论周期 T = 2π√(m/k)。
A19: 本表采用简化模型，不修正弹簧自身质量；若某根弹簧质量较大，可在后续分析阶段加入有效质量修正。

Sheet Trial记录
A1: Trial 记录｜每次释放一行
A3: 整批统一静止释放。每次 Trial 记录 x₀ = 释放长度 − 该弹簧的平衡长度；技术无效 Trial 直接删除，轻微但仍可用的异常写入备注。
A5: Trial编号 | B5: 弹簧编号 | C5: 重复编号 | D5: 视频文件名 | E5: 释放长度-平衡长度_mm | F5: 是否更换背景 | G5: 背景说明（可空） | H5: 备注（可空） | I5: 理论周期_s
A6: T001 | B6: S01 | D6: IMG_1538 | E6: 10 | F6: 否 | I6: =IFERROR(VLOOKUP(B6,弹簧设置!$A$6:$G$15,7,FALSE),"") -> 0.78992413
A7: T002 | B7: S01 | D7: IMG_1539 | E7: 10 | F7: 否 | I7: =IFERROR(VLOOKUP(B7,弹簧设置!$A$6:$G$15,7,FALSE),"") -> 0.78992413
A8: T003 | B8: S01 | D8: IMG_1540 | E8: 10 | F8: 否 | I8: =IFERROR(VLOOKUP(B8,弹簧设置!$A$6:$G$15,7,FALSE),"") -> 0.78992413
A9: T004 | B9: S01 | D9: IMG_1541 | E9: 10 | F9: 否 | I9: =IFERROR(VLOOKUP(B9,弹簧设置!$A$6:$G$15,7,FALSE),"") -> 0.78992413
A10: T005 | B10: S01 | D10: IMG_1542 | E10: 10 | F10: 是 | G10: 黑色泡沫 | I10: =IFERROR(VLOOKUP(B10,弹簧设置!$A$6:$G$15,7,FALSE),"") -> 0.78992413
A11: T006 | B11: S01 | D11: IMG_1543 | E11: 10 | F11: 是 | G11: 黑色泡沫 | I11: =IFERROR(VLOOKUP(B11,弹簧设置!$A$6:$G$15,7,FALSE),"") -> 0.78992413
A12: T007 | B12: S01 | D12: IMG_1544 | E12: 10 | F12: 是 | G12: 黑色泡沫 | I12: =IFERROR(VLOOKUP(B12,弹簧设置!$A$6:$G$15,7,FALSE),"") -> 0.78992413
A13: T008 | B13: S01 | D13: IMG_1545 | E13: 20 | F13: 是 | G13: 黑色泡沫 | I13: =IFERROR(VLOOKUP(B13,弹簧设置!$A$6:$G$15,7,FALSE),"") -> 0.78992413
A14: T009 | B14: S01 | D14: IMG_1546 | E14: 20 | F14: 是 | G14: 黑色泡沫 | I14: =IFERROR(VLOOKUP(B14,弹簧设置!$A$6:$G$15,7,FALSE),"") -> 0.78992413
A15: T010 | B15: S01 | D15: IMG_1549 | E15: 20 | F15: 是 | G15: 红色卡纸 | I15: =IFERROR(VLOOKUP(B15,弹簧设置!$A$6:$G$15,7,FALSE),"") -> 0.78992413
A16: T011 | B16: S01 | D16: IMG_1550 | E16: 20 | F16: 是 | G16: 粉色卡纸 | I16: =IFERROR(VLOOKUP(B16,弹簧设置!$A$6:$G$15,7,FALSE),"") -> 0.78992413
A17: T012 | B17: S01 | D17: IMG_1553 | E17: 20 | F17: 是 | G17: 画 | I17: =IFERROR(VLOOKUP(B17,弹簧设置!$A$6:$G$15,7,FALSE),"") -> 0.78992413
A18: T013 | B18: S01 | D18: IMG_1554 | E18: 20 | F18: 是 | G18: 画 | I18: =IFERROR(VLOOKUP(B18,弹簧设置!$A$6:$G$15,7,FALSE),"") -> 0.78992413
A19: T014 | B19: S01 | D19: IMG_1555 | E19: 20 | F19: 是 | G19: 画 | I19: =IFERROR(VLOOKUP(B19,弹簧设置!$A$6:$G$15,7,FALSE),"") -> 0.78992413
A20: T015 | B20: S01 | D20: IMG_1557 | E20: 30 | F20: 是 | G20: 紫色卡纸 | I20: =IFERROR(VLOOKUP(B20,弹簧设置!$A$6:$G$15,7,FALSE),"") -> 0.78992413
A21: T016 | B21: S01 | D21: IMG_1558 | E21: 30 | F21: 是 | G21: 粉色卡纸
A22: T017 | B22: S01 | D22: IMG_1559 | E22: 30 | F22: 否 | I22: =IFERROR(VLOOKUP(B22,弹簧设置!$A$6:$G$15,7,FALSE),"") -> 0.78992413
A23: T018 | B23: S01 | D23: IMG_1560 | E23: 30 | F23: 否 | I23: =IFERROR(VLOOKUP(B23,弹簧设置!$A$6:$G$15,7,FALSE),"") -> 0.78992413
A24: T019 | B24: S01 | D24: IMG_1561 | E24: 30 | F24: 是 | G24: 绿色卡纸 | I24: =IFERROR(VLOOKUP(B24,弹簧设置!$A$6:$G$15,7,FALSE),"") -> 0.78992413
A25: T020 | B25: S01 | D25: IMG_1562 | E25: 30 | F25: 是 | G25: 红色卡纸 | I25: =IFERROR(VLOOKUP(B25,弹簧设置!$A$6:$G$15,7,FALSE),"") -> 0.78992413
A26: T021 | B26: S01 | D26: IMG_1563 | E26: 30 | F26: 是 | G26: 橙色卡纸 | I26: =IFERROR(VLOOKUP(B26,弹簧设置!$A$6:$G$15,7,FALSE),"") -> 0.78992413
A27: T022 | B27: S01 | D27: IMG_1564 | E27: 40 | F27: 否 | I27: =IFERROR(VLOOKUP(B27,弹簧设置!$A$6:$G$15,7,FALSE),"") -> 0.78992413
A28: T023 | B28: S01 | D28: IMG_1565 | E28: 40 | F28: 是 | G28: 黑色泡沫 | I28: =IFERROR(VLOOKUP(B28,弹簧设置!$A$6:$G$15,7,FALSE),"") -> 0.78992413
A29: T024 | B29: S01 | D29: IMG_1566 | E29: 40 | F29: 是 | G29: 黑色泡沫 | I29: =IFERROR(VLOOKUP(B29,弹簧设置!$A$6:$G$15,7,FALSE),"") -> 0.78992413
A30: T025 | B30: S01 | D30: IMG_1567 | E30: 40 | F30: 是 | G30: 画 | I30: =IFERROR(VLOOKUP(B30,弹簧设置!$A$6:$G$15,7,FALSE),"") -> 0.78992413
A31: T026 | B31: S01 | D31: IMG_1568 | E31: 40 | F31: 是 | G31: 画 | I31: =IFERROR(VLOOKUP(B31,弹簧设置!$A$6:$G$15,7,FALSE),"") -> 0.78992413
A32: T027 | B32: S01 | D32: IMG_1569 | E32: 40 | F32: 是 | G32: 画 | I32: =IFERROR(VLOOKUP(B32,弹簧设置!$A$6:$G$15,7,FALSE),"") -> 0.78992413
A33: T028 | B33: S01 | D33: IMG_1570 | E33: 40 | F33: 是 | G33: 粉色卡纸 | I33: =IFERROR(VLOOKUP(B33,弹簧设置!$A$6:$G$15,7,FALSE),"") -> 0.78992413
A34: T029 | B34: S01 | D34: IMG_1571 | E34: 50 | F34: 是 | G34: 绿色卡纸 | I34: =IFERROR(VLOOKUP(B34,弹簧设置!$A$6:$G$15,7,FALSE),"") -> 0.78992413
A35: T030 | B35: S01 | D35: IMG_1572 | E35: 50 | F35: 是 | G35: 绿色卡纸 | I35: =IFERROR(VLOOKUP(B35,弹簧设置!$A$6:$G$15,7,FALSE),"") -> 0.78992413
A36: T031 | B36: S01 | D36: IMG_1573 | E36: 50 | F36: 是 | G36: 红色卡纸 | I36: =IFERROR(VLOOKUP(B36,弹簧设置!$A$6:$G$15,7,FALSE),"") -> 0.78992413
A37: T032 | B37: S01 | D37: IMG_1574 | E37: 50 | F37: 是 | G37: 紫色卡纸 | I37: =IFERROR(VLOOKUP(B37,弹簧设置!$A$6:$G$15,7,FALSE),"") -> 0.78992413
A38: T033 | B38: S01 | D38: IMG_1575 | E38: 50 | F38: 是 | G38: 紫色卡纸 | I38: =IFERROR(VLOOKUP(B38,弹簧设置!$A$6:$G$15,7,FALSE),"") -> 0.78992413
A39: T034 | B39: S01 | D39: IMG_1576 | E39: 50 | F39: 是 | G39: 粉色卡纸 | I39: =IFERROR(VLOOKUP(B39,弹簧设置!$A$6:$G$15,7,FALSE),"") -> 0.78992413
... A41: T036 | B41: S01 | D41: IMG_1578 | E41: 60 | F41: 是 | G41: 画 | I41: =IFERROR(VLOOKUP(B41,弹簧设置!$A$6:$G$15,7,FALSE),"") -> 0.78992413
A42: T037 | B42: S01 | D42: IMG_1579 | E42: 60 | F42: 否 | I42: =IFERROR(VLOOKUP(B42,弹簧设置!$A$6:$G$15,7,FALSE),"") -> 0.78992413
A43: T038 | B43: S01 | D43: IMG_1580 | E43: 60 | F43: 否 | I43: =IFERROR(VLOOKUP(B43,弹簧设置!$A$6:$G$15,7,FALSE),"") -> 0.78992413
...
